# Generated by Django 5.1 on 2024-08-24 21:40

import django.contrib.auth.validators
from django.db import migrations, models


class Migration(migrations.Migration):

    dependencies = [
        ('user', '0001_initial'),
    ]

    operations = [
        migrations.RemoveField(
            model_name='usuario',
            name='apellido',
        ),
        migrations.RemoveField(
            model_name='usuario',
            name='contrasena',
        ),
        migrations.RemoveField(
            model_name='usuario',
            name='nombre',
        ),
        migrations.AddField(
            model_name='usuario',
            name='city',
            field=models.CharField(blank=True, max_length=120, null=True),
        ),
        migrations.AddField(
            model_name='usuario',
            name='country',
            field=models.CharField(blank=True, max_length=120, null=True),
        ),
        migrations.AddField(
            model_name='usuario',
            name='gender',
            field=models.CharField(blank=True, choices=[('Male', 'Male'), ('Female', 'Female')], max_length=6, null=True),
        ),
        migrations.AddField(
            model_name='usuario',
            name='phone_number',
            field=models.CharField(blank=True, max_length=20, null=True, unique=True),
        ),
        migrations.AlterField(
            model_name='usuario',
            name='username',
            field=models.CharField(error_messages={'unique': 'A user with that username already exists.'}, help_text='Required. 150 characters or fewer. Letters, digits and @/./+/-/_ only.', max_length=150, unique=True, validators=[django.contrib.auth.validators.UnicodeUsernameValidator()], verbose_name='username'),
        ),
    ]
